<?xml version="1.0" ?>
<!-- =================================================================================== -->
<!-- |    This document was autogenerated by xacro from ../neurowalker/source/neurowalker/neurowalker/assets/neurowalker-v0/urdf/neurowalker.xacro | -->
<!-- |    EDITING THIS FILE BY HAND IS NOT RECOMMENDED                                 | -->
<!-- =================================================================================== -->
<robot name="neurowalker">
  <link name="base_link">
    <inertial>
      <origin rpy="0 0 0" xyz="-4.0647E-17 -2.3675E-17 -0.00046955"/>
      <mass value="1.0408"/>
      <inertia ixx="0.0011542" ixy="1.5544E-10" ixz="7.7333E-21" iyy="0.0039905" iyz="-3.097E-20" izz="0.0049674"/>
    </inertial>
    <visual>
      <origin rpy="0 0 0" xyz="0 0 0"/>
      <geometry>
        <mesh filename="../../meshes/simplified/stl/base_link.STL"/>
      </geometry>
      <material name="">
        <color rgba="0.79216 0.81961 0.93333 1"/>
      </material>
    </visual>
    <collision>
      <origin rpy="0 0 0" xyz="0 0 0"/>
      <geometry>
        <mesh filename="../../meshes/simplified/stl/base_link.STL"/>
      </geometry>
    </collision>
  </link>
  <link name="hip_link_1">
    <inertial>
      <origin rpy="0 0 0" xyz="0.0207539578220567 0.00016313993084466 -0.000157508593183945"/>
      <mass value="0.00976937887973851"/>
      <inertia ixx="4.36001352628253E-06" ixy="3.05074712305715E-11" ixz="1.09800410231598E-11" iyy="3.54065431889005E-06" iyz="-8.43037492910402E-22" izz="3.53980041929617E-06"/>
    </inertial>
    <visual>
      <origin rpy="0 0 0" xyz="0 0 0"/>
      <geometry>
        <mesh filename="../../meshes/simplified/stl/hip_link.STL"/>
      </geometry>
      <material name="">
        <color rgba="0.79216 0.81961 0.93333 1"/>
      </material>
    </visual>
    <collision>
      <origin rpy="0 0 0" xyz="0 0 0"/>
      <geometry>
        <mesh filename="../../meshes/simplified/stl/hip_link.STL"/>
      </geometry>
    </collision>
  </link>
  <link name="femur_link_1">
    <inertial>
      <origin rpy="0 0 0" xyz="0.039 -0.000267065647974397 1.30227414534182E-05"/>
      <mass value="0.0681610759338743"/>
      <inertia ixx="1.22383085422276E-05" ixy="1.5544030901566E-10" ixz="2.33365338510496E-21" iyy="1.88790791713266E-05" iyz="1.60983936131494E-21" izz="1.12330386801315E-05"/>
    </inertial>
    <visual>
      <origin rpy="0 0 0" xyz="0 0 0"/>
      <geometry>
        <mesh filename="../../meshes/simplified/stl/femur_link.STL"/>
      </geometry>
      <material name="">
        <color rgba="0.79216 0.81961 0.93333 1"/>
      </material>
    </visual>
    <collision>
      <origin rpy="0 0 0" xyz="0 0 0"/>
      <geometry>
        <mesh filename="../../meshes/simplified/stl/femur_link.STL"/>
      </geometry>
    </collision>
  </link>
  <link name="tibia_link_1">
    <inertial>
      <origin rpy="0 0 0" xyz="0.0863740398095008 -0.0136567529957215 2.8854666747154E-08"/>
      <mass value="0.0518953116111732"/>
      <inertia ixx="2.14028837547244E-05" ixy="1.20884063145876E-05" ixz="3.60427983546376E-11" iyy="5.18668393911014E-05" iyz="-1.36891234811654E-11" izz="4.38855876942104E-05"/>
    </inertial>
    <visual>
      <origin rpy="0 0 0" xyz="0 0 0"/>
      <geometry>
        <mesh filename="../../meshes/simplified/stl/tibia_link.STL"/>
      </geometry>
      <material name="">
        <color rgba="0.79216 0.81961 0.93333 1"/>
      </material>
    </visual>
    <collision>
      <origin rpy="0 0 0" xyz="0 0 0"/>
      <geometry>
        <mesh filename="../../meshes/simplified/stl/tibia_link.STL"/>
      </geometry>
    </collision>
  </link>
  <link name="foot_tip_link_1">
    <inertial>
      <origin rpy="0 0 0" xyz="0.00119417475728155 9.48943996844099E-20 -1.38897240469442E-19"/>
      <mass value="0.00345156312874398"/>
      <inertia ixx="1.55434275887049E-07" ixy="-1.7646776450454E-24" ixz="-3.90368160252396E-24" iyy="1.2879747429975E-07" iyz="-6.17628190706261E-24" izz="1.2879747429975E-07"/>
    </inertial>
    <visual>
      <origin rpy="0 0 0" xyz="0 0 0"/>
      <geometry>
        <mesh filename="../../meshes/simplified/stl/foot_tip_link.STL"/>
      </geometry>
      <material name="">
        <color rgba="0.694117647058824 0.0980392156862745 0.0980392156862745 1"/>
      </material>
    </visual>
    <collision>
      <origin rpy="0 0 0" xyz="0 0 0"/>
      <geometry>
        <mesh filename="../../meshes/simplified/stl/foot_tip_link.STL"/>
      </geometry>
    </collision>
  </link>
  <link name="hip_link_2">
    <inertial>
      <origin rpy="0 0 0" xyz="0.0207539578220567 0.00016313993084466 -0.000157508593183945"/>
      <mass value="0.00976937887973851"/>
      <inertia ixx="4.36001352628253E-06" ixy="3.05074712305715E-11" ixz="1.09800410231598E-11" iyy="3.54065431889005E-06" iyz="-8.43037492910402E-22" izz="3.53980041929617E-06"/>
    </inertial>
    <visual>
      <origin rpy="0 0 0" xyz="0 0 0"/>
      <geometry>
        <mesh filename="../../meshes/simplified/stl/hip_link.STL"/>
      </geometry>
      <material name="">
        <color rgba="0.79216 0.81961 0.93333 1"/>
      </material>
    </visual>
    <collision>
      <origin rpy="0 0 0" xyz="0 0 0"/>
      <geometry>
        <mesh filename="../../meshes/simplified/stl/hip_link.STL"/>
      </geometry>
    </collision>
  </link>
  <link name="femur_link_2">
    <inertial>
      <origin rpy="0 0 0" xyz="0.039 -0.000267065647974397 1.30227414534182E-05"/>
      <mass value="0.0681610759338743"/>
      <inertia ixx="1.22383085422276E-05" ixy="1.5544030901566E-10" ixz="2.33365338510496E-21" iyy="1.88790791713266E-05" iyz="1.60983936131494E-21" izz="1.12330386801315E-05"/>
    </inertial>
    <visual>
      <origin rpy="0 0 0" xyz="0 0 0"/>
      <geometry>
        <mesh filename="../../meshes/simplified/stl/femur_link.STL"/>
      </geometry>
      <material name="">
        <color rgba="0.79216 0.81961 0.93333 1"/>
      </material>
    </visual>
    <collision>
      <origin rpy="0 0 0" xyz="0 0 0"/>
      <geometry>
        <mesh filename="../../meshes/simplified/stl/femur_link.STL"/>
      </geometry>
    </collision>
  </link>
  <link name="tibia_link_2">
    <inertial>
      <origin rpy="0 0 0" xyz="0.0863740398095008 -0.0136567529957215 2.8854666747154E-08"/>
      <mass value="0.0518953116111732"/>
      <inertia ixx="2.14028837547244E-05" ixy="1.20884063145876E-05" ixz="3.60427983546376E-11" iyy="5.18668393911014E-05" iyz="-1.36891234811654E-11" izz="4.38855876942104E-05"/>
    </inertial>
    <visual>
      <origin rpy="0 0 0" xyz="0 0 0"/>
      <geometry>
        <mesh filename="../../meshes/simplified/stl/tibia_link.STL"/>
      </geometry>
      <material name="">
        <color rgba="0.79216 0.81961 0.93333 1"/>
      </material>
    </visual>
    <collision>
      <origin rpy="0 0 0" xyz="0 0 0"/>
      <geometry>
        <mesh filename="../../meshes/simplified/stl/tibia_link.STL"/>
      </geometry>
    </collision>
  </link>
  <link name="foot_tip_link_2">
    <inertial>
      <origin rpy="0 0 0" xyz="0.00119417475728155 9.48943996844099E-20 -1.38897240469442E-19"/>
      <mass value="0.00345156312874398"/>
      <inertia ixx="1.55434275887049E-07" ixy="-1.7646776450454E-24" ixz="-3.90368160252396E-24" iyy="1.2879747429975E-07" iyz="-6.17628190706261E-24" izz="1.2879747429975E-07"/>
    </inertial>
    <visual>
      <origin rpy="0 0 0" xyz="0 0 0"/>
      <geometry>
        <mesh filename="../../meshes/simplified/stl/foot_tip_link.STL"/>
      </geometry>
      <material name="">
        <color rgba="0.694117647058824 0.0980392156862745 0.0980392156862745 1"/>
      </material>
    </visual>
    <collision>
      <origin rpy="0 0 0" xyz="0 0 0"/>
      <geometry>
        <mesh filename="../../meshes/simplified/stl/foot_tip_link.STL"/>
      </geometry>
    </collision>
  </link>
  <link name="hip_link_3">
    <inertial>
      <origin rpy="0 0 0" xyz="0.0207539578220567 0.00016313993084466 -0.000157508593183945"/>
      <mass value="0.00976937887973851"/>
      <inertia ixx="4.36001352628253E-06" ixy="3.05074712305715E-11" ixz="1.09800410231598E-11" iyy="3.54065431889005E-06" iyz="-8.43037492910402E-22" izz="3.53980041929617E-06"/>
    </inertial>
    <visual>
      <origin rpy="0 0 0" xyz="0 0 0"/>
      <geometry>
        <mesh filename="../../meshes/simplified/stl/hip_link.STL"/>
      </geometry>
      <material name="">
        <color rgba="0.79216 0.81961 0.93333 1"/>
      </material>
    </visual>
    <collision>
      <origin rpy="0 0 0" xyz="0 0 0"/>
      <geometry>
        <mesh filename="../../meshes/simplified/stl/hip_link.STL"/>
      </geometry>
    </collision>
  </link>
  <link name="femur_link_3">
    <inertial>
      <origin rpy="0 0 0" xyz="0.039 -0.000267065647974397 1.30227414534182E-05"/>
      <mass value="0.0681610759338743"/>
      <inertia ixx="1.22383085422276E-05" ixy="1.5544030901566E-10" ixz="2.33365338510496E-21" iyy="1.88790791713266E-05" iyz="1.60983936131494E-21" izz="1.12330386801315E-05"/>
    </inertial>
    <visual>
      <origin rpy="0 0 0" xyz="0 0 0"/>
      <geometry>
        <mesh filename="../../meshes/simplified/stl/femur_link.STL"/>
      </geometry>
      <material name="">
        <color rgba="0.79216 0.81961 0.93333 1"/>
      </material>
    </visual>
    <collision>
      <origin rpy="0 0 0" xyz="0 0 0"/>
      <geometry>
        <mesh filename="../../meshes/simplified/stl/femur_link.STL"/>
      </geometry>
    </collision>
  </link>
  <link name="tibia_link_3">
    <inertial>
      <origin rpy="0 0 0" xyz="0.0863740398095008 -0.0136567529957215 2.8854666747154E-08"/>
      <mass value="0.0518953116111732"/>
      <inertia ixx="2.14028837547244E-05" ixy="1.20884063145876E-05" ixz="3.60427983546376E-11" iyy="5.18668393911014E-05" iyz="-1.36891234811654E-11" izz="4.38855876942104E-05"/>
    </inertial>
    <visual>
      <origin rpy="0 0 0" xyz="0 0 0"/>
      <geometry>
        <mesh filename="../../meshes/simplified/stl/tibia_link.STL"/>
      </geometry>
      <material name="">
        <color rgba="0.79216 0.81961 0.93333 1"/>
      </material>
    </visual>
    <collision>
      <origin rpy="0 0 0" xyz="0 0 0"/>
      <geometry>
        <mesh filename="../../meshes/simplified/stl/tibia_link.STL"/>
      </geometry>
    </collision>
  </link>
  <link name="foot_tip_link_3">
    <inertial>
      <origin rpy="0 0 0" xyz="0.00119417475728155 9.48943996844099E-20 -1.38897240469442E-19"/>
      <mass value="0.00345156312874398"/>
      <inertia ixx="1.55434275887049E-07" ixy="-1.7646776450454E-24" ixz="-3.90368160252396E-24" iyy="1.2879747429975E-07" iyz="-6.17628190706261E-24" izz="1.2879747429975E-07"/>
    </inertial>
    <visual>
      <origin rpy="0 0 0" xyz="0 0 0"/>
      <geometry>
        <mesh filename="../../meshes/simplified/stl/foot_tip_link.STL"/>
      </geometry>
      <material name="">
        <color rgba="0.694117647058824 0.0980392156862745 0.0980392156862745 1"/>
      </material>
    </visual>
    <collision>
      <origin rpy="0 0 0" xyz="0 0 0"/>
      <geometry>
        <mesh filename="../../meshes/simplified/stl/foot_tip_link.STL"/>
      </geometry>
    </collision>
  </link>
  <link name="hip_link_4">
    <inertial>
      <origin rpy="0 0 0" xyz="0.0207539578220567 0.00016313993084466 -0.000157508593183945"/>
      <mass value="0.00976937887973851"/>
      <inertia ixx="4.36001352628253E-06" ixy="3.05074712305715E-11" ixz="1.09800410231598E-11" iyy="3.54065431889005E-06" iyz="-8.43037492910402E-22" izz="3.53980041929617E-06"/>
    </inertial>
    <visual>
      <origin rpy="0 0 0" xyz="0 0 0"/>
      <geometry>
        <mesh filename="../../meshes/simplified/stl/hip_link.STL"/>
      </geometry>
      <material name="">
        <color rgba="0.79216 0.81961 0.93333 1"/>
      </material>
    </visual>
    <collision>
      <origin rpy="0 0 0" xyz="0 0 0"/>
      <geometry>
        <mesh filename="../../meshes/simplified/stl/hip_link.STL"/>
      </geometry>
    </collision>
  </link>
  <link name="femur_link_4">
    <inertial>
      <origin rpy="0 0 0" xyz="0.039 -0.000267065647974397 1.30227414534182E-05"/>
      <mass value="0.0681610759338743"/>
      <inertia ixx="1.22383085422276E-05" ixy="1.5544030901566E-10" ixz="2.33365338510496E-21" iyy="1.88790791713266E-05" iyz="1.60983936131494E-21" izz="1.12330386801315E-05"/>
    </inertial>
    <visual>
      <origin rpy="0 0 0" xyz="0 0 0"/>
      <geometry>
        <mesh filename="../../meshes/simplified/stl/femur_link.STL"/>
      </geometry>
      <material name="">
        <color rgba="0.79216 0.81961 0.93333 1"/>
      </material>
    </visual>
    <collision>
      <origin rpy="0 0 0" xyz="0 0 0"/>
      <geometry>
        <mesh filename="../../meshes/simplified/stl/femur_link.STL"/>
      </geometry>
    </collision>
  </link>
  <link name="tibia_link_4">
    <inertial>
      <origin rpy="0 0 0" xyz="0.0863740398095008 -0.0136567529957215 2.8854666747154E-08"/>
      <mass value="0.0518953116111732"/>
      <inertia ixx="2.14028837547244E-05" ixy="1.20884063145876E-05" ixz="3.60427983546376E-11" iyy="5.18668393911014E-05" iyz="-1.36891234811654E-11" izz="4.38855876942104E-05"/>
    </inertial>
    <visual>
      <origin rpy="0 0 0" xyz="0 0 0"/>
      <geometry>
        <mesh filename="../../meshes/simplified/stl/tibia_link.STL"/>
      </geometry>
      <material name="">
        <color rgba="0.79216 0.81961 0.93333 1"/>
      </material>
    </visual>
    <collision>
      <origin rpy="0 0 0" xyz="0 0 0"/>
      <geometry>
        <mesh filename="../../meshes/simplified/stl/tibia_link.STL"/>
      </geometry>
    </collision>
  </link>
  <link name="foot_tip_link_4">
    <inertial>
      <origin rpy="0 0 0" xyz="0.00119417475728155 9.48943996844099E-20 -1.38897240469442E-19"/>
      <mass value="0.00345156312874398"/>
      <inertia ixx="1.55434275887049E-07" ixy="-1.7646776450454E-24" ixz="-3.90368160252396E-24" iyy="1.2879747429975E-07" iyz="-6.17628190706261E-24" izz="1.2879747429975E-07"/>
    </inertial>
    <visual>
      <origin rpy="0 0 0" xyz="0 0 0"/>
      <geometry>
        <mesh filename="../../meshes/simplified/stl/foot_tip_link.STL"/>
      </geometry>
      <material name="">
        <color rgba="0.694117647058824 0.0980392156862745 0.0980392156862745 1"/>
      </material>
    </visual>
    <collision>
      <origin rpy="0 0 0" xyz="0 0 0"/>
      <geometry>
        <mesh filename="../../meshes/simplified/stl/foot_tip_link.STL"/>
      </geometry>
    </collision>
  </link>
  <link name="hip_link_5">
    <inertial>
      <origin rpy="0 0 0" xyz="0.0207539578220567 0.00016313993084466 -0.000157508593183945"/>
      <mass value="0.00976937887973851"/>
      <inertia ixx="4.36001352628253E-06" ixy="3.05074712305715E-11" ixz="1.09800410231598E-11" iyy="3.54065431889005E-06" iyz="-8.43037492910402E-22" izz="3.53980041929617E-06"/>
    </inertial>
    <visual>
      <origin rpy="0 0 0" xyz="0 0 0"/>
      <geometry>
        <mesh filename="../../meshes/simplified/stl/hip_link.STL"/>
      </geometry>
      <material name="">
        <color rgba="0.79216 0.81961 0.93333 1"/>
      </material>
    </visual>
    <collision>
      <origin rpy="0 0 0" xyz="0 0 0"/>
      <geometry>
        <mesh filename="../../meshes/simplified/stl/hip_link.STL"/>
      </geometry>
    </collision>
  </link>
  <link name="femur_link_5">
    <inertial>
      <origin rpy="0 0 0" xyz="0.039 -0.000267065647974397 1.30227414534182E-05"/>
      <mass value="0.0681610759338743"/>
      <inertia ixx="1.22383085422276E-05" ixy="1.5544030901566E-10" ixz="2.33365338510496E-21" iyy="1.88790791713266E-05" iyz="1.60983936131494E-21" izz="1.12330386801315E-05"/>
    </inertial>
    <visual>
      <origin rpy="0 0 0" xyz="0 0 0"/>
      <geometry>
        <mesh filename="../../meshes/simplified/stl/femur_link.STL"/>
      </geometry>
      <material name="">
        <color rgba="0.79216 0.81961 0.93333 1"/>
      </material>
    </visual>
    <collision>
      <origin rpy="0 0 0" xyz="0 0 0"/>
      <geometry>
        <mesh filename="../../meshes/simplified/stl/femur_link.STL"/>
      </geometry>
    </collision>
  </link>
  <link name="tibia_link_5">
    <inertial>
      <origin rpy="0 0 0" xyz="0.0863740398095008 -0.0136567529957215 2.8854666747154E-08"/>
      <mass value="0.0518953116111732"/>
      <inertia ixx="2.14028837547244E-05" ixy="1.20884063145876E-05" ixz="3.60427983546376E-11" iyy="5.18668393911014E-05" iyz="-1.36891234811654E-11" izz="4.38855876942104E-05"/>
    </inertial>
    <visual>
      <origin rpy="0 0 0" xyz="0 0 0"/>
      <geometry>
        <mesh filename="../../meshes/simplified/stl/tibia_link.STL"/>
      </geometry>
      <material name="">
        <color rgba="0.79216 0.81961 0.93333 1"/>
      </material>
    </visual>
    <collision>
      <origin rpy="0 0 0" xyz="0 0 0"/>
      <geometry>
        <mesh filename="../../meshes/simplified/stl/tibia_link.STL"/>
      </geometry>
    </collision>
  </link>
  <link name="foot_tip_link_5">
    <inertial>
      <origin rpy="0 0 0" xyz="0.00119417475728155 9.48943996844099E-20 -1.38897240469442E-19"/>
      <mass value="0.00345156312874398"/>
      <inertia ixx="1.55434275887049E-07" ixy="-1.7646776450454E-24" ixz="-3.90368160252396E-24" iyy="1.2879747429975E-07" iyz="-6.17628190706261E-24" izz="1.2879747429975E-07"/>
    </inertial>
    <visual>
      <origin rpy="0 0 0" xyz="0 0 0"/>
      <geometry>
        <mesh filename="../../meshes/simplified/stl/foot_tip_link.STL"/>
      </geometry>
      <material name="">
        <color rgba="0.694117647058824 0.0980392156862745 0.0980392156862745 1"/>
      </material>
    </visual>
    <collision>
      <origin rpy="0 0 0" xyz="0 0 0"/>
      <geometry>
        <mesh filename="../../meshes/simplified/stl/foot_tip_link.STL"/>
      </geometry>
    </collision>
  </link>
  <link name="hip_link_6">
    <inertial>
      <origin rpy="0 0 0" xyz="0.0207539578220567 0.00016313993084466 -0.000157508593183945"/>
      <mass value="0.00976937887973851"/>
      <inertia ixx="4.36001352628253E-06" ixy="3.05074712305715E-11" ixz="1.09800410231598E-11" iyy="3.54065431889005E-06" iyz="-8.43037492910402E-22" izz="3.53980041929617E-06"/>
    </inertial>
    <visual>
      <origin rpy="0 0 0" xyz="0 0 0"/>
      <geometry>
        <mesh filename="../../meshes/simplified/stl/hip_link.STL"/>
      </geometry>
      <material name="">
        <color rgba="0.79216 0.81961 0.93333 1"/>
      </material>
    </visual>
    <collision>
      <origin rpy="0 0 0" xyz="0 0 0"/>
      <geometry>
        <mesh filename="../../meshes/simplified/stl/hip_link.STL"/>
      </geometry>
    </collision>
  </link>
  <link name="femur_link_6">
    <inertial>
      <origin rpy="0 0 0" xyz="0.039 -0.000267065647974397 1.30227414534182E-05"/>
      <mass value="0.0681610759338743"/>
      <inertia ixx="1.22383085422276E-05" ixy="1.5544030901566E-10" ixz="2.33365338510496E-21" iyy="1.88790791713266E-05" iyz="1.60983936131494E-21" izz="1.12330386801315E-05"/>
    </inertial>
    <visual>
      <origin rpy="0 0 0" xyz="0 0 0"/>
      <geometry>
        <mesh filename="../../meshes/simplified/stl/femur_link.STL"/>
      </geometry>
      <material name="">
        <color rgba="0.79216 0.81961 0.93333 1"/>
      </material>
    </visual>
    <collision>
      <origin rpy="0 0 0" xyz="0 0 0"/>
      <geometry>
        <mesh filename="../../meshes/simplified/stl/femur_link.STL"/>
      </geometry>
    </collision>
  </link>
  <link name="tibia_link_6">
    <inertial>
      <origin rpy="0 0 0" xyz="0.0863740398095008 -0.0136567529957215 2.8854666747154E-08"/>
      <mass value="0.0518953116111732"/>
      <inertia ixx="2.14028837547244E-05" ixy="1.20884063145876E-05" ixz="3.60427983546376E-11" iyy="5.18668393911014E-05" iyz="-1.36891234811654E-11" izz="4.38855876942104E-05"/>
    </inertial>
    <visual>
      <origin rpy="0 0 0" xyz="0 0 0"/>
      <geometry>
        <mesh filename="../../meshes/simplified/stl/tibia_link.STL"/>
      </geometry>
      <material name="">
        <color rgba="0.79216 0.81961 0.93333 1"/>
      </material>
    </visual>
    <collision>
      <origin rpy="0 0 0" xyz="0 0 0"/>
      <geometry>
        <mesh filename="../../meshes/simplified/stl/tibia_link.STL"/>
      </geometry>
    </collision>
  </link>
  <link name="foot_tip_link_6">
    <inertial>
      <origin rpy="0 0 0" xyz="0.00119417475728155 9.48943996844099E-20 -1.38897240469442E-19"/>
      <mass value="0.00345156312874398"/>
      <inertia ixx="1.55434275887049E-07" ixy="-1.7646776450454E-24" ixz="-3.90368160252396E-24" iyy="1.2879747429975E-07" iyz="-6.17628190706261E-24" izz="1.2879747429975E-07"/>
    </inertial>
    <visual>
      <origin rpy="0 0 0" xyz="0 0 0"/>
      <geometry>
        <mesh filename="../../meshes/simplified/stl/foot_tip_link.STL"/>
      </geometry>
      <material name="">
        <color rgba="0.694117647058824 0.0980392156862745 0.0980392156862745 1"/>
      </material>
    </visual>
    <collision>
      <origin rpy="0 0 0" xyz="0 0 0"/>
      <geometry>
        <mesh filename="../../meshes/simplified/stl/foot_tip_link.STL"/>
      </geometry>
    </collision>
  </link>
  <joint name="hip_joint_1" type="revolute">
    <parent link="base_link"/>
    <child link="hip_link_1"/>
    <origin rpy="0 0 0.7853981633974483" xyz="0.172664 0.092664 0.0"/>
    <axis xyz="0 0 1"/>
    <limit effort="1.9613" lower="-2.0943951023931953" upper="2.0943951023931953" velocity="5.8178"/>
  </joint>
  <joint name="femur_joint_1" type="revolute">
    <parent link="hip_link_1"/>
    <child link="femur_link_1"/>
    <origin rpy="-1.5707963267948966 0 0" xyz="0.0415 0 0"/>
    <axis xyz="0 0 1"/>
    <limit effort="1.9613" lower="-2.0943951023931953" upper="2.0943951023931953" velocity="5.8178"/>
  </joint>
  <joint name="tibia_joint_1" type="revolute">
    <parent link="femur_link_1"/>
    <child link="tibia_link_1"/>
    <origin rpy="3.141592653589793 0 0" xyz="0.078 0 0"/>
    <axis xyz="0 0 1"/>
    <limit effort="1.9613" lower="-2.0943951023931953" upper="2.0943951023931953" velocity="5.8178"/>
  </joint>
  <joint name="foot_tip_joint_1" type="fixed">
    <parent link="tibia_link_1"/>
    <child link="foot_tip_link_1"/>
    <origin rpy="0 0 -0.3490658503988659" xyz="0.15110741780330628 -0.03625413519252088 0"/>
  </joint>
  <joint name="hip_joint_2" type="revolute">
    <parent link="base_link"/>
    <child link="hip_link_2"/>
    <origin rpy="0 0 -0.7853981633974483" xyz="0.172664 -0.092664 0.0"/>
    <axis xyz="0 0 1"/>
    <limit effort="1.9613" lower="-2.0943951023931953" upper="2.0943951023931953" velocity="5.8178"/>
  </joint>
  <joint name="femur_joint_2" type="revolute">
    <parent link="hip_link_2"/>
    <child link="femur_link_2"/>
    <origin rpy="-1.5707963267948966 0 0" xyz="0.0415 0 0"/>
    <axis xyz="0 0 1"/>
    <limit effort="1.9613" lower="-2.0943951023931953" upper="2.0943951023931953" velocity="5.8178"/>
  </joint>
  <joint name="tibia_joint_2" type="revolute">
    <parent link="femur_link_2"/>
    <child link="tibia_link_2"/>
    <origin rpy="3.141592653589793 0 0" xyz="0.078 0 0"/>
    <axis xyz="0 0 1"/>
    <limit effort="1.9613" lower="-2.0943951023931953" upper="2.0943951023931953" velocity="5.8178"/>
  </joint>
  <joint name="foot_tip_joint_2" type="fixed">
    <parent link="tibia_link_2"/>
    <child link="foot_tip_link_2"/>
    <origin rpy="0 0 -0.3490658503988659" xyz="0.15110741780330628 -0.03625413519252088 0"/>
  </joint>
  <joint name="hip_joint_3" type="revolute">
    <parent link="base_link"/>
    <child link="hip_link_3"/>
    <origin rpy="0 0 1.5707963267948966" xyz="0 0.12191 0.0"/>
    <axis xyz="0 0 1"/>
    <limit effort="1.9613" lower="-2.0943951023931953" upper="2.0943951023931953" velocity="5.8178"/>
  </joint>
  <joint name="femur_joint_3" type="revolute">
    <parent link="hip_link_3"/>
    <child link="femur_link_3"/>
    <origin rpy="-1.5707963267948966 0 0" xyz="0.0415 0 0"/>
    <axis xyz="0 0 1"/>
    <limit effort="1.9613" lower="-2.0943951023931953" upper="2.0943951023931953" velocity="5.8178"/>
  </joint>
  <joint name="tibia_joint_3" type="revolute">
    <parent link="femur_link_3"/>
    <child link="tibia_link_3"/>
    <origin rpy="3.141592653589793 0 0" xyz="0.078 0 0"/>
    <axis xyz="0 0 1"/>
    <limit effort="1.9613" lower="-2.0943951023931953" upper="2.0943951023931953" velocity="5.8178"/>
  </joint>
  <joint name="foot_tip_joint_3" type="fixed">
    <parent link="tibia_link_3"/>
    <child link="foot_tip_link_3"/>
    <origin rpy="0 0 -0.3490658503988659" xyz="0.15110741780330628 -0.03625413519252088 0"/>
  </joint>
  <joint name="hip_joint_4" type="revolute">
    <parent link="base_link"/>
    <child link="hip_link_4"/>
    <origin rpy="0 0 -1.5707963267948966" xyz="0 -0.12191 0.0"/>
    <axis xyz="0 0 1"/>
    <limit effort="1.9613" lower="-2.0943951023931953" upper="2.0943951023931953" velocity="5.8178"/>
  </joint>
  <joint name="femur_joint_4" type="revolute">
    <parent link="hip_link_4"/>
    <child link="femur_link_4"/>
    <origin rpy="-1.5707963267948966 0 0" xyz="0.0415 0 0"/>
    <axis xyz="0 0 1"/>
    <limit effort="1.9613" lower="-2.0943951023931953" upper="2.0943951023931953" velocity="5.8178"/>
  </joint>
  <joint name="tibia_joint_4" type="revolute">
    <parent link="femur_link_4"/>
    <child link="tibia_link_4"/>
    <origin rpy="3.141592653589793 0 0" xyz="0.078 0 0"/>
    <axis xyz="0 0 1"/>
    <limit effort="1.9613" lower="-2.0943951023931953" upper="2.0943951023931953" velocity="5.8178"/>
  </joint>
  <joint name="foot_tip_joint_4" type="fixed">
    <parent link="tibia_link_4"/>
    <child link="foot_tip_link_4"/>
    <origin rpy="0 0 -0.3490658503988659" xyz="0.15110741780330628 -0.03625413519252088 0"/>
  </joint>
  <joint name="hip_joint_5" type="revolute">
    <parent link="base_link"/>
    <child link="hip_link_5"/>
    <origin rpy="0 0 2.356194490192345" xyz="-0.172664 0.092664 0.0"/>
    <axis xyz="0 0 1"/>
    <limit effort="1.9613" lower="-2.0943951023931953" upper="2.0943951023931953" velocity="5.8178"/>
  </joint>
  <joint name="femur_joint_5" type="revolute">
    <parent link="hip_link_5"/>
    <child link="femur_link_5"/>
    <origin rpy="-1.5707963267948966 0 0" xyz="0.0415 0 0"/>
    <axis xyz="0 0 1"/>
    <limit effort="1.9613" lower="-2.0943951023931953" upper="2.0943951023931953" velocity="5.8178"/>
  </joint>
  <joint name="tibia_joint_5" type="revolute">
    <parent link="femur_link_5"/>
    <child link="tibia_link_5"/>
    <origin rpy="3.141592653589793 0 0" xyz="0.078 0 0"/>
    <axis xyz="0 0 1"/>
    <limit effort="1.9613" lower="-2.0943951023931953" upper="2.0943951023931953" velocity="5.8178"/>
  </joint>
  <joint name="foot_tip_joint_5" type="fixed">
    <parent link="tibia_link_5"/>
    <child link="foot_tip_link_5"/>
    <origin rpy="0 0 -0.3490658503988659" xyz="0.15110741780330628 -0.03625413519252088 0"/>
  </joint>
  <joint name="hip_joint_6" type="revolute">
    <parent link="base_link"/>
    <child link="hip_link_6"/>
    <origin rpy="0 0 -2.356194490192345" xyz="-0.172664 -0.092664 0.0"/>
    <axis xyz="0 0 1"/>
    <limit effort="1.9613" lower="-2.0943951023931953" upper="2.0943951023931953" velocity="5.8178"/>
  </joint>
  <joint name="femur_joint_6" type="revolute">
    <parent link="hip_link_6"/>
    <child link="femur_link_6"/>
    <origin rpy="-1.5707963267948966 0 0" xyz="0.0415 0 0"/>
    <axis xyz="0 0 1"/>
    <limit effort="1.9613" lower="-2.0943951023931953" upper="2.0943951023931953" velocity="5.8178"/>
  </joint>
  <joint name="tibia_joint_6" type="revolute">
    <parent link="femur_link_6"/>
    <child link="tibia_link_6"/>
    <origin rpy="3.141592653589793 0 0" xyz="0.078 0 0"/>
    <axis xyz="0 0 1"/>
    <limit effort="1.9613" lower="-2.0943951023931953" upper="2.0943951023931953" velocity="5.8178"/>
  </joint>
  <joint name="foot_tip_joint_6" type="fixed">
    <parent link="tibia_link_6"/>
    <child link="foot_tip_link_6"/>
    <origin rpy="0 0 -0.3490658503988659" xyz="0.15110741780330628 -0.03625413519252088 0"/>
  </joint>
</robot>
